<?xml version="1.0"?>
<?xml-model href="https://raw.githubusercontent.com/ros/urdfdom/master/xsd/urdf.xsd" ?>
<robot name="BB25" xmlns="http://www.ros.org">
    
    <material name="white">
        <color rgba="1 1 1 1"/>
    </material>

    <material name="orange">
        <color rgba="1 0.3 0.1 1"/>
    </material>

    <material name="blue">
        <color rgba="0.2 0.2 1 1"/>
    </material>

    <material name="black">
        <color rgba="0 0 0 1"/>
    </material>

    <!-- Fixed base with contact surface -->
    <link name="base">
        <collision>
            <origin xyz="0 0 -0.05"/>
            <geometry>
                <box size="1.0 1.0 0.1"/>
            </geometry>
        </collision>
    </link>
    
    <!-- The metal chassis, servos, and circuitry all combine to a single rigid body -->
    <link name="chassis">
        <inertial>
            <origin xyz="-0.06 0 0.05"/>
            <mass value="1.0"/>
            <inertia ixx="0.0006528333333333334" ixy="0" ixz="0" iyy="0.0014283533333333334" iyz="0" izz="0.0019126466666666668"/>
        </inertial>
        <visual>
            <origin xyz="-0.06 0 0.05"/>
            <geometry>
                <box size="0.12 0.1 0.05"/>
            </geometry>
            <material name="black"/>
        </visual>
        <collision>
            <origin xyz="-0.06 0 0.05"/>
            <geometry>
                <box size="0.12 0.1 0.05"/>
            </geometry>
        </collision>
    </link>
    
    <!-- The differential drive wheels on the left and right side of the chassis. The local wheel axis is -Z. -->
    <link name="right_wheel">
        <inertial>
            <origin xyz="0 0 0"/>
            <mass value="0.1"/>
            <inertia ixx="0.0001" ixy="0" ixz="0" iyy="0.0001" iyz="0" izz="0.0001"/>
        </inertial>
        <visual>
            <origin xyz="0 0 0"/>
            <geometry>
                <cylinder radius="0.035" length="0.005"/>
            </geometry>
            <material name="orange"/>
        </visual>
        <collision>
            <origin xyz="0 0 0"/>
            <geometry>
                <cylinder radius="0.035" length="0.005"/>
            </geometry>
        </collision>
    </link>
    <link name="left_wheel">
        <inertial>
            <origin xyz="0 0 0"/>
            <mass value="0.1"/>
            <inertia ixx="0.0001" ixy="0" ixz="0" iyy="0.0001" iyz="0" izz="0.0001"/>
        </inertial>
        <visual>
            <origin xyz="0 0 0"/>
            <geometry>
                <cylinder radius="0.035" length="0.005"/>
            </geometry>
            <material name="blue"/>
        </visual>
        <collision>
            <origin xyz="0 0 0"/>
            <geometry>
                <cylinder radius="0.035" length="0.005"/>
            </geometry>
        </collision>
    </link>
    
    <!-- The rear caster wheel that balances the robot -->
    <link name="rear_wheel">
        <inertial>
            <origin xyz="0 0 0"/>
            <mass value="0.1"/>
            <inertia ixx="0.0001" ixy="0" ixz="0" iyy="0.0001" iyz="0" izz="0.0001"/>
        </inertial>
        <visual>
            <origin xyz="0 0 0"/>
            <geometry>
                <sphere radius="0.0127"/>
            </geometry>
            <material name="white"/>
        </visual>
        <collision>
            <origin xyz="0 0 0"/>
            <geometry>
                <sphere radius="0.0127"/>
            </geometry>
        </collision>
    </link>

    <!-- The chassis has free motion relative to the base -->
    <joint name="6DoF" type="floating">
        <parent link="base"/>
        <child link="chassis"/>
    </joint>

    <!-- The right and left wheels can rotate about the Y-axis of the chassis, local Z-axis of the wheels -->
    <joint name="right" type="continuous">
        <parent link="chassis"/>
        <child link="right_wheel"/>
        <origin xyz="-0.04645 -0.0555 0.035" rpy="-1.570796327 0 0"/>
        <axis xyz="0 1 0"/>
    </joint>
    <joint name="left" type="continuous">
        <parent link="chassis"/>
        <child link="left_wheel"/>
        <origin xyz="-0.04645 0.0555 0.035" rpy="1.570796327 0 0"/>
        <axis xyz="0 1 0"/>
    </joint>
    
    <!-- The rear caster wheel can rotate about the Y-axis of the chassis -->
    <joint name="rear" type="continuous">
        <parent link="chassis" />
        <child link="rear_wheel" />
        <origin xyz="-0.130752 0 0.0127" />
        <axis xyz="0 1 0" />
    </joint>
    
</robot>
